
<robot name="r2d3">

    <material name="white">
        <color rgba="1 1 1 1" />
    </material>

    <material name="orange">
        <color rgba="1 0.3 0.1 1"/>
    </material>

    <material name="blue">
        <color rgba="0.2 0.2 1 1"/>
    </material>

    <material name="black">
        <color rgba="0 0 0 1"/>
    </material>

    <gazebo reference="chassis">
    <material>Gazebo/Red</material>
    </gazebo>
<gazebo>
        <plugin name='diff_drive' filename='libgazebo_ros_diff_drive.so'>
    
    
            <!-- Wheel Information -->
            <left_joint>contleft_joint</left_joint>
            <right_joint>contright_joint</right_joint>
            <wheel_separation>0.35</wheel_separation>
            <wheel_diameter>0.05</wheel_diameter>
    

            <!-- Limits -->
            <max_wheel_torque>200</max_wheel_torque>
            <max_wheel_acceleration>10.0</max_wheel_acceleration>
    

            <!-- Output -->
            <odometry_frame>odom</odometry_frame>
            <robot_base_frame>link</robot_base_frame>

            <publish_odom>true</publish_odom>
            <publish_odom_tf>true</publish_odom_tf>
            <publish_wheel_tf>true</publish_wheel_tf>
    
    
        </plugin>
    </gazebo>

<gazebo reference="caster_wheel">
    <material>Gazebo/Black</material>
    <mu1 value="0.001"/>
    <mu2 value="0.001"/>
</gazebo>



<!-- hokuyo -->
  <gazebo reference="laser_frame">
        <material>Gazebo/Red</material>
 
        <sensor name="laser" type="ray">
            <pose> 0 0 0 0 0 0 </pose>
            <visualize>true</visualize>
            <update_rate>10</update_rate>
            <ray>
                <scan>
                    <horizontal>
                        <samples>360</samples>
                        <min_angle>-3.14</min_angle>
                        <max_angle>3.14</max_angle>
                    </horizontal>
                </scan>
                <range>
                    <min>0.3</min>
                    <max>12</max>
                </range>
            </ray>
            <plugin name="laser_controller" filename="libgazebo_ros_ray_sensor.so">
                <ros>
                    <argument>~/out:=scan</argument>
                </ros>
                <output_type>sensor_msgs/LaserScan</output_type>
                <frame_name>laser_frame</frame_name>
            </plugin>
        </sensor>
    </gazebo>



























    <!-- BASE LINK -->

    <link name="link">
    </link>
<!-- Hokuyo Laser -->

<joint name="hokuyo_joint" type="fixed">
    <axis xyz="0 1 0" />
    <origin xyz="0.2 0 0.175" rpy="0 0 0"/>
    <parent link="chassis"/>
    <child link="laser_frame"/>
  </joint>

  <!-- Hokuyo Laser -->
  <link name="laser_frame">
    <collision>
      <origin xyz="0 0 0" rpy="0 0 0"/>
      <geometry>
    <cylinder length="0.05" radius="0.05"/>
      </geometry>
      <material name="orange"/>
    </collision>

    <visual>
      <origin xyz="0 0 0" rpy="0 0 0"/>
      <geometry>
        <cylinder length="0.05" radius="0.05"/>
      </geometry>
      <material name="orange"/>
    </visual>

    <inertial>
      <mass value="1e-5" />
      <origin xyz="0 0 0" rpy="0 0 0"/>
      <inertia ixx="1e-6" ixy="0" ixz="0" iyy="1e-6" iyz="0" izz="1e-6" />
    </inertial>
  </link>














    <!-- CHASSIS LINK -->

    <joint name="chassis_joint" type="fixed">
        <parent link="link"/>
        <child link="chassis"/>
        <origin xyz="0.1 0 0"/>
    </joint>

    <link name="chassis">
        <visual>
            <origin xyz="0.15 0 0.075"/>
            <geometry>
                <box size="0.3 0.3 0.15"/>
            </geometry>
            <material name="blue"/>
        </visual>
        <collision>
            <origin xyz="0.15 0 0.075"/>
            <geometry>
                <box size="0.3 0.3 0.15"/>
            </geometry>
        </collision>
    <inertial>
        <mass value="0.5"/>
        <inertia ixx="0.00469" ixy="0.0" ixz="0.0"
                    iyy="0.00469" iyz="0.0"
                    izz="0.0075" />
        <origin xyz="0.15 0 0.075" rpy="0 0 0"/>
    </inertial>

    </link>
    <joint name="contright_joint" type="continuous">
        <parent link="chassis"/>
        <child link="right_wheel"/>
        <axis xyz="0 0 1"/>
        <origin rpy="0 1.57075 1.57075 " xyz="0.06 0.175 0"/>
    </joint>

    <link name="right_wheel">
        <visual>
            <geometry>
                <cylinder length="0.05" radius="0.05"/>
            </geometry>
            
            <material name="orange"/>
        </visual>
        <collision>
            <geometry>
                <cylinder length="0.05" radius="0.05"/>
            </geometry>
        </collision>

        <inertial>
        <mass value="0.1"/>
        <inertia ixx="8.334e-05" ixy="0.0" ixz="0.0"
                    iyy="8.334e-05" iyz="0.0"
                    izz="0.000125" />
        <origin xyz="0 0 0" rpy="0 0 0"/>
    </inertial>

    </link>


    <joint name="contleft_joint" type="continuous">
        <parent link="chassis"/>
        <child link="left_wheel"/>
        <axis xyz="0 0 1"/>
        <origin rpy="0 1.57075 1.57075 " xyz="0.06 -0.175 0"/>
    </joint>
    <link name="left_wheel">
        <visual>
            <geometry>
                <cylinder length="0.05" radius="0.05"/>
            </geometry>
            
            <material name="orange"/>
        </visual>
        <collision>
            <geometry>
                <cylinder length="0.05" radius="0.05"/>
            </geometry>
        </collision>

        <inertial>
        <mass value="0.1"/>
        <inertia ixx="8.334e-05" ixy="0.0" ixz="0.0"
                    iyy="8.334e-05" iyz="0.0"
                    izz="0.000125" />
        <origin xyz="0 0 0" rpy="0 0 0"/>
    </inertial>
    </link>


    <joint name="caster_wheel_joint" type="fixed">
        <parent link="chassis"/>
        <child link="caster_wheel"/>
        <origin xyz="0.24 0 0" rpy="0 0 0"/>
    </joint>

    <link name="caster_wheel">
    <visual>
        <geometry>
            <sphere radius="0.05" />
        </geometry>
        <material name="black"/>
    </visual>

        <collision>
            <geometry>
            <sphere radius="0.05" />
        </geometry>
        <material name="black"/>
        </collision>
    <inertial>
        <mass value="0.1"/>
        <inertia ixx="0.00010" ixy="0.0" ixz="0.0"
                    iyy="0.00010" iyz="0.0"
                    izz="0.00010" />
        <origin xyz="0 0 0" rpy="0 0 0"/>
    </inertial>

</link>



</robot>